export const catchAsyncError = (fun) => {
    return async (req, res, next) => {
        try {
            await fun(req, res, next);
        } catch (error) {
            next(error)
        }
    }
}